Workbook

Sheet index
B1: ครู | C1: รายการ
A2: 1 | C2: ใบสั่งซื้อหนังสือเรียน | D2: https://docs.google.com/spreadsheets/d/15wSXchJU6FHen-VFOoQPwxwgfdORD6IqmBmJIoFg6ys/edit?gid=707846140#gid=707846140
A3: 2 | C3: ส่งโครงการ | D3: https://drive.google.com/drive/u/2/folders/18loU2-QbOvZi722j7CewxR6GyYJZHoSk
C9: งานศิลปหัตถกรรมนักเรียน ปีการศึกษา 2568 ระดับเขตพื้นที่การศึกษา สพป. เชียงราย เขต 3 | D9: งานศิลปหัตถกรรมนักเรียนระดับเขตพื้นที่การศึกษา ครั้งที่ 73 ปีการศึกษา 2568

Sheet บันทึก
A1: บันทึก ของชานนท์
A2: วันที่ | B2: การแก้ไขล่าสุด
A3: 244394 | B3: ร่างรายชื่อ ป.1 จากการรวมคะแนนความสามารถภาษา ของ อ.3
A4: 244401 | B4: ร่างรายชื่อ อ.3 ป.2 นักเรียนป.2 แยกห้อง ย้ายห้องบ้างคน
A5: 244481 | B5: จัดนักเรียนเข้าชั้น ใส่ชื่อครูประจำชั้น
A6: 244482 | B6: แก้ไขชื่อ ถูกภาคิน ป.1/1 (ผิดภาคิณ) -->ครูภัณฑิรา

Sheet รายชื่อครู
B1: ขอความกรุณาไม่แชร์ลิงก์ข้อมูลใน Google sheet นี้ออกนอกโรงเรียนนะครับ
J3: ชื่อ - สกุล ว่าง | K3: ครูย้าย
A4: {='ป.1-ป.6'!A2:A2} -> ร่าง-รายชื่อนักเรียนปีการศึกษา 1/2569 | I4: 1 | J4: ฉัตรดนัย ใยญาติ ม.2 | K4: รพีพรรณ มาลารัตน์
A5: วันที่ 18 พฤษภาคม 2569 | I5: 2 | K5: ชัชพล ลำดวน
I6: 3 | K6: มาลินี ดอนมูล
A7: ชั้น | B7: ห้อง1 | C7: ห้อง2 | D7: ห้อง3 | I7: 4 | K7: ศุภกานต์ ชื่นจิต
A8: อ.2 | B8: ครูอนุบาลใหม่1 | C8: ครูศิรินกรณ์ สุยะ | I8: 5 | K8: อรปรียา กาแก้ว
A9: อ.3 | B9: ครูอัฐชาฎา หัสกิจ | C9: ครูอนุบาลใหม่2 | I9: 6
A10: ป.1 | B10: ครูภัณฑิรา เมืองปัญโญ | C10: ครูฐิตาภรณ์ สายอิ่นแก้ว | D10: ครูปฏิภาณ สมฟองทอง | I10: 7
A11: ป.2 | B11: ครูชานนท์ จันต๊ะคาด | C11: ครููไทยใหม่ | D11: ครูวิทยใหม่ | I11: 8
A12: ป.3 | B12: ครูสุจินดา ใจกล้า | C12: ครูพุฒิชัย ไฝเครือ | I12: 9
A13: ป.4 | B13: ครููใหม่ / ครูเลอพงษ์ ปัญญาดี | C13: ครูภาณุพงค์ ยาจันทร์ | I13: 10
A14: ป.5 | B14: ครูกัญญาวีร์ เวียงมูล/ครูวิจิตรา เย็นจิตต์ | C14: ครูนิลาวรรณ สายพรหม | I14: 11
A15: ป.6 | B15: ครูเอกพงษ์ ใจต๊ะ | C15: ครูชาญณรงค์ โลดแจ้ง | I15: 12
A16: ม.1 | B16: ครูจารุกิตติ์ ยิ่งสมบูรณ์ชัย | C16: ครูสุรศักดิ์ เนตรทิพย์ | I16: 13
A17: ม.2 | B17: ครูขวัญชัย โกแสนตอ /ครูฉัตรดนัย ใยญาติ | I17: 14
A18: ม.3 | B18: ครูกรกกฎ โรจนนิล/ครูณัฐพล เหม็งทะเหล็ก | I18: 15
I19: 16
A21: ชั้น | B21: ห้อง1 | C21: ห้อง2 | D21: ห้อง3 | E21: รวม
A22: อ.2 | B22: 72 | C22: รอรายชื่อนิ่งจะแบ่งเป็น2ห้อง | D22: - | E22: =SUM(B22:D22) -> 72
A23: อ.3 | B23: 21 | C23: 22 | D23: - | E23: =SUM(B23:D23) -> 43 | F23: =SUM(E21:E23) -> 115 | G23: 4
A24: ป.1 | B24: 27 | C24: 27 | D24: 27 | E24: =SUM(B24:D24) -> 81
A25: ป.2 | B25: 26 | C25: 24 | D25: 23 | E25: =SUM(B25:D25) -> 73
A26: ป.3 | B26: 29 | C26: 29 | D26: - | E26: =SUM(B26:D26) -> 58 | F26: =SUM(E24:E26) -> 212 | G26: 8
A27: ป.4 | B27: 24 | C27: 23 | D27: - | E27: =SUM(B27:D27) -> 47
A28: ป.5 | B28: 28 | C28: 27 | D28: - | E28: =SUM(B28:D28) -> 55
A29: ป.6 | B29: 23 | C29: 22 | D29: - | E29: =SUM(B29:D29) -> 45 | F29: =SUM(E27:E29) -> 147 | G29: 12
A30: ม.1 | B30: 25 | C30: 25 | D30: - | E30: =SUM(B30:D30) -> 50 | G30: 4
A31: ม.2 | B31: 29 | C31: - | D31: - | E31: =SUM(B31:D31) -> 29
A32: ม.3 | B32: 38 | C32: - | D32: - | E32: =SUM(B32:D32) -> 38 | F32: =SUM(E30:E32) -> 117
D33: รวม | E33: =SUM(E21:E32) -> 591 | F33: คน | G33: =SUM(G22:G32) -> 28 | H33: ห้อง

Sheet จำนวนนักเรียน
A2: รายชื่อนักเรียนปี ภาคเรียนที่ 2 การศึกษา 2569
G3: วันที่ 21 เดือน พฤษภาคม พ.ศ .2568
B4: ห้อง 1 | E4: ห้อง2 | H4: ห้อง3 | N4: รวม
A5: ชั้น | B5: ชาย | C5: หญิง | D5: รวม | E5: ชาย | F5: หญิง | G5: รวม | H5: ชาย | I5: หญิง | J5: รวม | L5: ชาย | M5: หญิง
A6: อ.2 | B6: 17 | C6: 19 | D6: =B6+C6 -> 36 | E6: 14 | F6: 21 | G6: =E6+F6 -> 35 | H6: 0 | I6: 0 | J6: =H6+I6 -> 0 | L6: =B6+E6+H6 -> 31 | M6: =C6+F6+I6 -> 40 | N6: =D6+G6+J6 -> 71
A7: อ.3 | B7: 10 | C7: 11 | D7: =B7+C7 -> 21 | E7: 11 | F7: 10 | G7: =E7+F7 -> 21 | H7: 0 | I7: 0 | J7: =H7+I7 -> 0 | L7: =B7+E7+H7 -> 21 | M7: =C7+F7+I7 -> 21 | N7: =D7+G7+J7 -> 42
A8: รวม อ.2-อ3 | B8: =SUM(B6:B7) -> 27 | C8: =SUM(C6:C7) -> 30 | D8: =B8+C8 -> 57 | E8: =SUM(E6:E7) -> 25 | F8: =SUM(F6:F7) -> 31 | G8: =E8+F8 -> 56 | H8: 0 | I8: 0 | J8: 0 | L8: =B8+E8+H8 -> 52 | M8: =C8+F8+I8 -> 61 | N8: =SUM(N6:N7) -> 113
A9: ป.1 | B9: 15 | C9: 12 | D9: =B9+C9 -> 27 | E9: 14 | F9: 11 | G9: =E9+F9 -> 25 | H9: 14 | I9: 11 | J9: =H9+I9 -> 25 | L9: =B9+E9+H9 -> 43 | M9: =C9+F9+I9 -> 34 | N9: =D9+G9+J9 -> 77
A10: ป.2 | B10: =COUNTIF('ป.1-ป.6'!D130:D155,"เด็กชาย") -> 12 | C10: =COUNTIF('ป.1-ป.6'!D130:D155,"เด็กหญิง") -> 14 | D10: =B10+C10 -> 26 | E10: =COUNTIF('ป.1-ป.6'!D171:D200,"เด็กชาย") -> 12 | F10: =COUNTIF('ป.1-ป.6'!D171:D200,"เด็กหญิง") -> 12 | G10: =E10+F10 -> 24 | H10: 12 | I10: 11 | J10: =H10+I10 -> 23 | L10: =B10+E10+H10 -> 36 | M10: =C10+F10+I10 -> 37 | N10: =D10+G10+J10 -> 73
A11: ป.3 | B11: 10 | C11: 19 | D11: =B11+C11 -> 29 | E11: 11 | F11: 18 | G11: =E11+F11 -> 29 | H11: 0 | I11: 0 | J11: =H11+I11 -> 0 | L11: =B11+E11+H11 -> 21 | M11: =C11+F11+I11 -> 37 | N11: =D11+G11 -> 58
A12: รวม ป.1-ป.3 | B12: =SUM(B9:B11) -> 37 | C12: =SUM(C9:C11) -> 45 | D12: =B12+C12 -> 82 | E12: =SUM(E9:E11) -> 37 | F12: =SUM(F9:F11) -> 41 | G12: =E12+F12 -> 78 | J12: =H12+I12 -> 0 | L12: =B12+E12+H12 -> 74 | M12: =C12+F12+I12 -> 86 | N12: =SUM(N9:N11) -> 208
A13: ป.4 | B13: 12 | C13: 12 | D13: =B13+C13 -> 24 | E13: 9 | F13: 14 | G13: =E13+F13 -> 23 | J13: =H13+I13 -> 0 | L13: =B13+E13+H13 -> 21 | M13: =C13+F13+I13 -> 26 | N13: =D13+G13 -> 47
A14: ป.5 | B14: 14 | C14: 14 | D14: =B14+C14 -> 28 | E14: 14 | F14: 13 | G14: =E14+F14 -> 27 | J14: =H14+I14 -> 0 | L14: =B14+E14+H14 -> 28 | M14: =C14+F14+I14 -> 27 | N14: =D14+G14 -> 55
A15: ป.6 | B15: 13 | C15: 10 | D15: =B15+C15 -> 23 | E15: 9 | F15: 13 | G15: =E15+F15 -> 22 | J15: =H15+I15 -> 0 | L15: =B15+E15+H15 -> 22 | M15: =C15+F15+I15 -> 23 | N15: =D15+G15 -> 45
A16: รวม ป.4-ป.6 | B16: =SUM(B13:B15) -> 39 | C16: =SUM(C13:C15) -> 36 | D16: =B16+C16 -> 75 | E16: =SUM(E13:E15) -> 32 | F16: =SUM(F13:F15) -> 40 | G16: =E16+F16 -> 72 | H16: =SUM(H13:H15) -> 0 | I16: =SUM(I13:I15) -> 0 | J16: =H16+I16 -> 0 | L16: =B16+E16+H16 -> 71 | M16: =C16+F16+I16 -> 76 | N16: =SUM(N13:N15) -> 147
A17: รวม ป.1-ป6 | B17: =B16+B12 -> 76 | C17: =C16+C12 -> 81 | D17: =B17+C17 -> 157 | E17: =E16+E12 -> 69 | F17: =F16+F12 -> 81 | G17: =E17+F17 -> 150 | J17: =H17+I17 -> 0 | L17: =B17+E17+H17 -> 145 | M17: =C17+F17+I17 -> 162 | N17: =N16+N12 -> 355
A18: ม.1 | B18: 10 | C18: 14 | D18: =B18+C18 -> 24 | E18: 10 | F18: 14 | G18: =E18+F18 -> 24 | J18: =H18+I18 -> 0 | L18: =B18+E18+H18 -> 20 | M18: =C18+F18+I18 -> 28 | N18: =D18+G18 -> 48
A19: ม.2 | B19: 14 | C19: 15 | D19: =B19+C19 -> 29 | G19: =E19+F19 -> 0 | J19: =H19+I19 -> 0 | L19: =B19+E19+H19 -> 14 | M19: =C19+F19+I19 -> 15 | N19: =D19+G19 -> 29
A20: ม.3 | B20: 17 | C20: 21 | D20: =B20+C20 -> 38 | G20: =E20+F20 -> 0 | J20: =H20+I20 -> 0 | L20: =B20+E20+H20 -> 17 | M20: =C20+F20+I20 -> 21 | N20: =D20+G20 -> 38
A21: รวม ม.1-3 | B21: =SUM(B18:B20) -> 41 | C21: =SUM(C18:C20) -> 50 | D21: =SUM(D18:D20) -> 91 | E21: =SUM(E18:E20) -> 10 | F21: =SUM(F18:F20) -> 14 | G21: =SUM(G18:G20) -> 24 | H21: 0 | I21: 0 | J21: 0 | L21: =B21+E21+H21 -> 51 | M21: =C21+F21+I21 -> 64 | N21: =SUM(N18:N20) -> 115
B22: นักเรียนรวม | N22: =N8+N12+N16+N21 -> 583

Sheet อ.2-อ.3
A1: โรงเรียนบ้านพญาไพร
A2: ร่าง-รายชื่อนักเรียนปีการศึกษา 1/2569
A4: ชั้นอนุบาล 2/1 | D4: ครูประจำชั้น ครูอนุบาลใหม่1
A6: ที่ | B6: เลข นร. | C6: เลขประจำตัวประชาชน | D6: ชื่อ - สกุล
A7: 1 | B7: 3255 | C7: 0-5799-00064-42-4 | D7: ด.ช. | E7: คิรากร | F7: นายป่าง | G7: อ.2/1
A8: 2 | B8: 3257 | D8: ด.ช. | E8: จะดอวิ | F8: ลาหู่นะ | G8: อ.2/1
A9: 3 | B9: 3260 | C9: G-685700-002358 | D9: ด.ช. | E9: จะลอแส | F9: ลาหู่นะ | G9: อ.2/1
A10: 4 | B10: 3261 | D10: ด.ช. | E10: จะสอ | F10: ลาหู่นะ | G10: อ.2/1
A11: 5 | B11: 3262 | D11: ด.ช. | E11: จะส้อ | F11: มาเยอะ | G11: อ.2/1
A12: 6 | B12: 3263 | C12: G-685700-002374 | D12: ด.ช. | E12: จะสือติ | F12: ลาหู่นะ | G12: อ.2/1
A13: 7 | B13: 3264 | D13: ด.ช. | E13: จะหย่อ | F13: ลาหู่นะ | G13: อ.2/1
A14: 8 | B14: 3266 | C14: G-675700-002331 | D14: ด.ช. | E14: ดะวุฒิ | F14: ลาหู่นะ | G14: อ.2/1
A15: 9 | B15: 3268 | D15: ด.ช. | E15: ธงชัย | F15: จะหวะ | G15: อ.2/1
A16: 10 | B16: 3269 | C16: 0-5715-00021-74-7 | D16: ด.ช. | E16: ธนภัทร | F16: ลาหู่นะ | G16: อ.2/1
A17: 11 | B17: 3271 | C17: 1-5799-02091-13-3 | D17: ด.ช. | E17: ธนวัฒน์ | F17: สัจจาเมือง | G17: อ.2/1
A18: 12 | B18: 3272 | C18: 0-5799-00065-73-1 | D18: ด.ช. | E18: นิธาน | F18: เชือหมึกุ | G18: อ.2/1
A19: 13 | B19: 3274 | C19: 0-5715-00021-20-8 | D19: ด.ช. | E19: นิบูล | F19: ลาหู่นะ | G19: อ.2/1
A20: 14 | B20: 3276 | D20: ด.ช. | E20: ปิยะพล | F20: เชอหมื่อ | G20: อ.2/1
A21: 15 | B21: 3280 | C21: G-685700-002391 | D21: ด.ช. | E21: ย่าโบซือ | F21: ลาหู่นะ | G21: อ.2/1
A22: 16 | B22: 3282 | C22: 1-5788-00139-64-1 | D22: ด.ช. | E22: วชิรพงศ์ | F22: แซ่หอ | G22: อ.2/1
A23: 17 | B23: 3283 | C23: 1-5715-00156-25-0 | D23: ด.ช. | E23: วรินทร | F23: ศิรันดร์กุล | G23: อ.2/1
A24: 18 | B24: 3286 | C24: 1-5715-00154-66-4 | D24: ด.ญ. | E24: กัญญา | F24: แซ่เหาะ | G24: อ.2/1
A25: 19 | B25: 3287 | C25: 1-5799-02080-61-1 | D25: ด.ญ. | E25: กัญญารัตน์ | F25: แซ่จัง | G25: อ.2/1
A26: 20 | B26: 3288 | C26: 1-5715-00154-85-1 | D26: ด.ญ. | E26: กัญญาวีร์ | F26: แซ่ยี่ | G26: อ.2/1
A27: 21 | B27: 3290 | C27: G-685700-002421 | D27: ด.ญ. | E27: ขิหมี่ละ | F27: พายอกู่ | G27: อ.2/1
A28: 22 | B28: 3294 | D28: ด.ญ. | E28: เดือน | F28: ตาคำ | G28: อ.2/1
A29: 23 | B29: 3296 | C29: 1-5799-02101-01-5 | D29: ด.ญ. | E29: ธนิดา | F29: อางี่ | G29: อ.2/1
A30: 24 | B30: 3299 | C30: 1-5715-00153-93-5 | D30: ด.ญ. | E30: นันทิภาคย์ | F30: แซ่ฝู | G30: อ.2/1
A31: 25 | B31: 3302 | D31: ด.ญ. | E31: นาดอซาวิ | F31: ลาหู่นะ | G31: อ.2/1
A32: 26 | B32: 3305 | C32: G-685700-002471 | D32: ด.ญ. | E32: นาโทซา | F32: ลาหู่นะ | G32: อ.2/1
A33: 27 | B33: 3306 | D33: ด.ญ. | E33: นาสือโบ | F33: ลาหู่นะ | G33: อ.2/1
A34: 28 | B34: 3307 | D34: ด.ญ. | E34: นีสี่วิ | F34: ลาหู่นะ | G34: อ.2/1
A35: 29 | B35: 3311 | C35: G-685700-002463 | D35: ด.ญ. | E35: มะสอคา | F35: ลาหู่นะ | G35: อ.2/1
A36: 30 | B36: 3312 | C36: G-685700-002447 | D36: ด.ญ. | E36: มะสี่ละ | F36: ลาหู่นะ | G36: อ.2/1
A37: 31 | B37: 3313 | D37: ด.ญ. | E37: มีโบวิ | F37: ลาหู่นะ | G37: อ.2/1
A38: 32 | B38: 3314 | C38: G-675700-001971 | D38: ด.ญ. | E38: มีวีแซ | F38: ลาหู่นะ | G38: อ.2/1
A39: 33 | B39: 3315 | D39: ด.ญ. | E39: เยลามา | F39: ลาหู่เมอ | G39: อ.2/1
A40: 34 | B40: 3323 | C40: 1-5799-02105-40-1 | D40: ด.ญ. | E40: อัจฉริสา | F40: แซ่จัง | G40: อ.2/1
A41: 35 | B41: 3325 | D41: ด.ญ. | E41: อีและ | F41: ลาหู่นะ | G41: อ.2/1
A42: 36 | B42: 3326 | C42: 1-5799-02074-59-0 | D42: ด.ญ. | E42: ไอรีณ | F42: เยซอกู่ | G42: อ.2/1
...

Sheet ป.1-ป.6
A1: โรงเรียนบ้านพญาไพร
A2: ร่าง-รายชื่อนักเรียนปีการศึกษา 1/2569
A4: ชั้นประถมศึกษาปีที่ 1/1 | D4: ครูประจำชั้น ครูภัณฑิรา เมืองปัญโญ
A6: ที่ | B6: เลข นร. | C6: เลขประจำตัวประชาชน | D6: ชื่อ - สกุล | G6: คะแนน | H6: นับ1-20
A7: 1 | B7: 3100 | C7: 571500010354 | D7: เด็กชาย | E7: กิตพจน์ | F7: นายป่าง | G7: 2 | H7: 0
A8: 2 | B8: 3134 | C8: G655700005187 | D8: เด็กชาย | E8: จะงะ | F8: ลาหู่น่ะ | G8: 18 | H8: 0
A9: 3 | B9: 3102 | C9: G665700017185 | D9: เด็กชาย | E9: จะดอซา | F9: ลิจา | G9: 8 | H9: 3
A10: 4 | B10: 3135 | C10: G665700015956 | D10: เด็กชาย | E10: จะดะสือ | F10: ลาหู่นะ | G10: 17 | H10: 10
A11: 5 | B11: 3104 | C11: 1579901972519 | D11: เด็กชาย | E11: ชัยกร | F11: สัจจาเมือง | G11: 7 | H11: 9
A12: 6 | B12: 3117 | C12: 1578800125631 | D12: เด็กชาย | E12: ชาติชาย | F12: หมื่อแล | G12: 0 | H12: 0 | L12: ไม่มา
A13: 7 | B13: 3140 | C13: 1579902000731 | D13: เด็กชาย | E13: นพดล | F13: เคียงสุวรรณ | G13: 13 | H13: 9
A14: 8 | B14: 3109 | C14: 571500006217 | D14: เด็กชาย | E14: ภาคิน | F14: มิตรนิรันดร์ | G14: 11 | H14: 0
A15: 9 | B15: 3215 | C15: G685700042775 | D15: เด็กชาย | E15: ยะปะ | F15: ลาหู่นะ | G15: 20 | H15: 10
A16: 10 | B16: 3141 | C16: 1579902010826 | D16: เด็กชาย | E16: ภาคภูมิ | F16: ศีลธรรมดี | G16: 5 | H16: 10
A17: 11 | B17: 3146 | C17: 1579901986625 | D17: เด็กชาย | E17: สรวิชญ์ | F17: แซ่แถะ | G17: 2 | H17: 8
A18: 12 | B18: 3147 | C18: G665700017177 | D18: เด็กชาย | E18: หวู่หลี่ | F18: ลาหู่นะ | G18: 20 | H18: 10 | I18: ชอยคุย
A19: 13 | B19: 3118 | C19: 1571500149458 | D19: เด็กหญิง | E19: กมลพร | F19: แสงพลโรจน์ศรี | G19: 9 | H19: 10
A20: 14 | B20: 3119 | C20: 571500009925 | D20: เด็กหญิง | E20: ขวัญจิรา | F20: ลาหู่นะ | G20: 6 | H20: 18
A21: 15 | B21: 3151 | C21: 1100704838963 | D21: เด็กหญิง | E21: ขวัญฤทัย | F21: แซ่ซู | G21: 3 | H21: 10
A22: 16 | B22: 3152 | C22: G665700017525 | D22: เด็กหญิง | E22: เจ๋งมอญ | F22: ไทยใหญ่ | G22: 19 | H22: 10
A23: 17 | B23: 3170 | C23: 1579901970621 | D23: เด็กหญิง | E23: ธัญสินี | F23: เจริญจันทมณี | G23: 15 | H23: 10
A24: 18 | B24: 3123 | C24: G665700017665 | D24: เด็กหญิง | E24: นาดะ | F24: ลาหู่นะ | G24: 12 | H24: 10
A25: 19 | B25: 3156 | C25: G665700017541 | D25: เด็กหญิง | E25: นาสือ | F25: ลาหู่นะ | G25: 20 | H25: 10
A26: 20 | B26: 3157 | C26: 1578800126727 | D26: เด็กหญิง | E26: นิยะดา | F26: จะปา | G26: 8 | H26: 10
A27: 21 | B27: 3237 | C27: G675700002251 | D27: เด็กหญิง | E27: บูอยู่ | F27: มาเยอะ ย้ายไป รร.ไตรมิตร | G27: 16 | H27: pass | L27: ย้าย ไตรมิตร
A28: 22 | B28: 3127 | C28: G675700061346 | D28: เด็กหญิง | E28: ลินดา | F28: ลาหู่นะ | G28: 13 | H28: 9
A29: 23 | B29: 3327 | D29: เด็กชาย | E29: จอจอละ | F29: ลาหู่นะ | G29: โบสถ์คริสต์ ไม่มากลับพม่า | L29: ไม่มา
A30: 24 | B30: 3328 | D30: เด็กชาย | E30: จะพือ(3) | F30: ลาหู่นะ | G30: โบสถ์คริสต์ | H30: 10
A31: 25 | B31: 3329 | D31: เด็กชาย | E31: จะฟะ | F31: ลาหู่นะ | G31: โบสถ์คริสต์ | H31: 10
A32: 26 | B32: 3334 | D32: เด็กหญิง | E32: นาดอชาวิ | F32: ลาหู่นะ | G32: โบสถ์คริสต์ | H32: 2
A33: 27 | B33: 3336 | D33: เด็กหญิง | E33: นามู | F33: ลาหู่นะ | G33: โบสถ์คริสต์ | H33: 9
C39: ชาย | D39: =COUNTIF(D7:D33,"เด็กชาย") -> 15
C40: หญิง | D40: =COUNTIF(D7:D33,"เด็กหญิง") -> 12 | F40: รวม | G40: =I40+K40 -> 28 | H40: ช | I40: 10 | J40: ญ | K40: 18
C41: รวม | D41: =SUM(D39:D40) -> 27 | L41: วันที่ 21 พ.ค. 2569
A42: โรงเรียนบ้านพญาไพร
A43: =A2 -> ร่าง-รายชื่อนักเรียนปีการศึกษา 1/2569
A45: ชั้นประถมศึกษาปีที่ 1/2 | D45: ครูประจำชั้น ครูฐิตาภรณ์ สายอิ่นแก้ว
A47: ที่ | B47: เลข นร. | C47: เลขประจำตัวประชาชน | D47: ชื่อ - สกุล | G47: คะแนน
A48: 1 | B48: 3132 | C48: 571500006764 | D48: เด็กชาย | E48: กวีวัธน์ | F48: เชอมือ | G48: 8
A49: 2 | B49: 3101 | C49: G665700016006 | D49: เด็กชาย | E49: จะก๊ะซา | F49: ลิจา | G49: 10
...

Sheet ม.1-ม.3
A1: โรงเรียนบ้านพญาไพร
A2: ร่าง-รายชื่อนักเรียนปีการศึกษา 1/2569
A4: ชั้นมัธยมศึกษาปีที่ 1/1 | D4: ครูประจำชั้น ครูจารุกิตติ์ ยิ่งสมบูรณ์ชัย
A6: ที่ | B6: เลข นร. | C6: เลขประจำตัวประชาชน | D6: ชื่อ - สกุล
A7: 1 | B7: 2686 | C7: 571500031394 | D7: เด็กชาย | E7: จะแฮ | F7: ลาหู่นะ
A8: 2 | B8: 2689 | C8: 1571500127012 | D8: เด็กชาย | E8: ชัยวัฒน์ | F8: แซ่ถุง
A9: 3 | B9: 2690 | C9: 1571500123912 | D9: เด็กชาย | E9: ฐิติพงศ์ | F9: ลอซัง
A10: 4 | B10: 2695 | C10: 1571500125125 | D10: เด็กชาย | E10: ณัฐชนน | F10: แซ่พู่
A11: 5 | B11: 2694 | C11: 1571500125079 | D11: เด็กชาย | E11: บุญทิวา | F11: โรจน์ขันติโชติ
A12: 6 | B12: 2701 | C12: 1571500124579 | D12: เด็กชาย | E12: ไพรพญา | F12: เชอมือ
A13: 7 | B13: 2702 | C13: 571500032021 | D13: เด็กชาย | E13: ยูหน่าส่า | F13: ลาหู่นะ
A14: 8 | B14: 2703 | C14: 1571500125371 | D14: เด็กชาย | E14: รชตะ | F14: แซ่ฝู
A15: 9 | B15: 2706 | C15: 1571500124960 | D15: เด็กชาย | E15: วรชัย | F15: แซ่ม้า
A16: 10 | B16: 2719 | C16: 1571500122525 | D16: เด็กหญิง | E16: กรณิกา | F16: แซ่หล่อ
A17: 11 | B17: 2720 | C17: 571500002467 | D17: เด็กหญิง | E17: เขมนิจ | F17: ไทยใหญ่
A18: 12 | B18: 2721 | C18: 571500001606 | D18: เด็กหญิง | E18: ชลลดา | F18: อาเต๊อะ
A19: 13 | B19: 2722 | C19: 1571500127322 | D19: เด็กหญิง | E19: ณิชชยา | F19: แซ่หลอ
A20: 14 | B20: 2634 | C20: G635700044832 | D20: เด็กหญิง | E20: ดีสิ | F20: ลาหู่นะ
A21: 15 | B21: 2732 | C21: 8571576099475 | D21: เด็กหญิง | E21: นุชนภา | F21: ซางสู้
A22: 16 | B22: 2733 | C22: 1571500125940 | D22: เด็กหญิง | E22: เบญจา | F22: แซ่พู่
A23: 17 | B23: 2647 | C23: 1579901560695 | D23: เด็กหญิง | E23: พาขวัญ | F23: แซ่โก่
A24: 18 | B24: 2752 | C24: 571500031378 | D24: เด็กหญิง | E24: พิมพ์พา | F24: ลาหู่นะ
A25: 19 | B25: 2649 | C25: G635700044859 | D25: เด็กหญิง | E25: พีแหละ | F25: ลาหู่
A26: 20 | B26: 2742 | C26: 571500031408 | D26: เด็กหญิง | E26: ลีเหมย | F26: ลาหู่นะ
A27: 21 | B27: 2738 | C27: 1571500125281 | D27: เด็กหญิง | E27: วนิดา | F27: เยซอกู่
A28: 22 | B28: 3097 | C28: 1579901624251 | D28: เด็กหญิง | E28: ศิวาพร | F28: ละหู่นะ
A29: 23 | B29: 3253 | C29: 1571500119851 | D29: เด็กชาย | E29: มานพ | F29: ยิ่งโชติ | G29: นักเรียนใหม่
A30: 24 | B30: 2953 | C30: 1577000019224 | D30: เด็กหญิง | E30: อรรัมภา | F30: บาหลา | G30: นักเรียนใหม่ ลง dmc แล้ว
C39: ชาย | D39: =COUNTIF(D7:D33,"เด็กชาย") -> 10
C40: หญิง | D40: =COUNTIF(D7:D33,"เด็กหญิง") -> 14
C41: รวม | D41: =SUM(D39:D40) -> 24 | L41: ='ป.1-ป.6'!L41 -> วันที่ 21 พ.ค. 2569
A42: โรงเรียนบ้านพญาไพร
A43: =A2 -> ร่าง-รายชื่อนักเรียนปีการศึกษา 1/2569
A45: ชั้นมัธยมศึกษาปีที่ 1/2 | D45: ครูประจำชั้น ครูสุรศักดิ์ เนตรทิพย์
A47: ที่ | B47: เลข นร. | C47: เลขประจำตัวประชาชน | D47: ชื่อ - สกุล
A48: 1 | B48: 2685 | C48: 571500032056 | D48: เด็กชาย | E48: จะพือ | F48: ลาหู่นะ
A49: 2 | B49: 2687 | C49: 571500001568 | D49: เด็กชาย | E49: จักรธร | F49: ลาหู่นะ
A50: 3 | B50: 2688 | C50: 1571500127349 | D50: เด็กชาย | E50: จารุกิตติ์ | F50: ปิดศักดิ์
A51: 4 | B51: 2697 | C51: 1571500126521 | D51: เด็กชาย | E51: ปยุต | F51: แซ่ยี่
A52: 5 | B52: 2708 | C52: 1571500123131 | D52: เด็กชาย | E52: วิวรรธน์ | F52: เชอหมื่อ
...

Sheet ย้ายเข้า-นักเรียนใหม่
B1: ที่ | C1: เลข นร. | D1: เลขประจำตัวประชาชน | E1: ชื่อ1 | F1: ชื่อ | G1: สกุล | H1: ห้อง | I1: ที่ | J1: 1
B2: 1 | C2: 3252 | D2: 1579901869815 | E2: เด็กหญิง | F2: พรนภา | G2: พรสวรรค์คีรี | H2: ป.3/2 | K2: ลง DMC แล้ว
B3: 2 | C3: 3253 | D3: 1571500119851 | E3: เด็กชาย | F3: มานพ | G3: ยิ่งโชติ | H3: ม.1/1
B4: 3 | C4: 3254 | D4: G685700050476 | E4: เด็กหญิง | F4: มณี | G4: ลาหู่นะ | H4: ป.2/1 | K4: ลง DMC แล้ว
B5: 4 | C5: 3255 | D5: 0-5799-00064-42-4 | E5: ด.ช. | F5: คิรากร | G5: นายป่าง | H5: อ.2/1 | I5: 1 | J5: นักเรียนใหม่
B6: 5 | C6: 3256 | D6: 1-5788-00143-97-4 | E6: ด.ช. | F6: จรณินท์ | G6: เยซอกู่ | H6: อ.2/2 | I6: 56 | J6: นักเรียนใหม่
B7: 6 | C7: 3257 | E7: ด.ช. | F7: จะดอวิ | G7: ลาหู่นะ | H7: อ.2/1 | I7: 7 | J7: นักเรียนใหม่
B8: 7 | C8: 3258 | E8: ด.ช. | F8: จะดาแส | G8: ลาหู่นะ | H8: อ.2/2 | I8: 42 | J8: นักเรียนใหม่
B9: 8 | C9: 3259 | D9: G-685700-002196 | E9: ด.ช. | F9: จะนู | G9: ลาหู่นะ | H9: อ.2/2 | I9: 40 | J9: นักเรียนใหม่
B10: 9 | C10: 3260 | D10: G-685700-002358 | E10: ด.ช. | F10: จะลอแส | G10: ลาหู่นะ | H10: อ.2/1 | I10: 4 | J10: นักเรียนใหม่
B11: 10 | C11: 3261 | E11: ด.ช. | F11: จะสอ | G11: ลาหู่นะ | H11: อ.2/1 | I11: 25 | J11: นักเรียนใหม่
B12: 11 | C12: 3262 | E12: ด.ช. | F12: จะส้อ | G12: มาเยอะ | H12: อ.2/1 | I12: 6 | J12: นักเรียนใหม่
B13: 12 | C13: 3263 | D13: G-685700-002374 | E13: ด.ช. | F13: จะสือติ | G13: ลาหู่นะ | H13: อ.2/1 | I13: 24 | J13: นักเรียนใหม่
B14: 13 | C14: 3264 | E14: ด.ช. | F14: จะหย่อ | G14: ลาหู่นะ | H14: อ.2/1 | I14: 26 | J14: นักเรียนใหม่
B15: 14 | C15: 3265 | E15: ด.ช. | F15: จิรเมธ | G15: ลาหู่ | H15: อ.2/2 | I15: 61 | J15: นักเรียนใหม่
B16: 15 | C16: 3266 | D16: G-675700-002331 | E16: ด.ช. | F16: ดะวุฒิ | G16: ลาหู่นะ | H16: อ.2/1 | I16: 23 | J16: นักเรียนใหม่
B17: 16 | C17: 3267 | E17: ด.ช. | F17: เตชินท์ | G17: ล่าทวย | H17: อ.2/2 | I17: 62 | J17: นักเรียนใหม่
B18: 17 | C18: 3268 | E18: ด.ช. | F18: ธงชัย | G18: จะหวะ | H18: อ.2/1 | I18: 8 | J18: นักเรียนใหม่
B19: 18 | C19: 3269 | D19: 0-5715-00021-74-7 | E19: ด.ช. | F19: ธนภัทร | G19: ลาหู่นะ | H19: อ.2/1 | I19: 3 | J19: นักเรียนใหม่
B20: 19 | C20: 3270 | D20: 1-5788-00139-38-1 | E20: ด.ช. | F20: ธนวรรธน์ | G20: จามีกรธารา | H20: อ.2/2 | I20: 37 | J20: นักเรียนใหม่
B21: 20 | C21: 3271 | D21: 1-5799-02091-13-3 | E21: ด.ช. | F21: ธนวัฒน์ | G21: สัจจาเมือง | H21: อ.2/1 | I21: 1 | J21: นักเรียนใหม่
B22: 21 | C22: 3272 | D22: 0-5799-00065-73-1 | E22: ด.ช. | F22: นิธาน | G22: เชือหมึกุ | H22: อ.2/1 | I22: 22 | J22: นักเรียนใหม่
B23: 22 | C23: 3273 | D23: 0-5799-00065-74-9 | E23: ด.ช. | F23: นิธิป | G23: เชือหมึกุ | H23: อ.2/2 | I23: 39 | J23: นักเรียนใหม่
B24: 23 | C24: 3274 | D24: 0-5715-00021-20-8 | E24: ด.ช. | F24: นิบูล | G24: ลาหู่นะ | H24: อ.2/1 | I24: 21 | J24: นักเรียนใหม่
B25: 24 | C25: 3275 | D25: G-685700-002340 | E25: ด.ช. | F25: ป้อหลู่ | G25: ลาหู่นะ | H25: อ.2/2 | I25: 59 | J25: นักเรียนใหม่
B26: 25 | C26: 3276 | E26: ด.ช. | F26: ปิยะพล | G26: เชอหมื่อ | H26: อ.2/1 | I26: 27 | J26: นักเรียนใหม่
B27: 26 | C27: 3277 | D27: 1-5715-00153-60-9 | E27: ด.ช. | F27: ภาคิน | G27: แซ่ซู | H27: อ.2/2 | I27: 55 | J27: นักเรียนใหม่
B28: 27 | C28: 3278 | D28: G-685700-002366 | E28: ด.ช. | F28: มะซื่อต้า | G28: ลาหู่นะ | H28: อ.2/2 | I28: 60 | J28: นักเรียนใหม่
B29: 28 | C29: 3279 | E29: ด.ช. | F29: ยะอื่อ | G29: ลาหู่นะ | H29: อ.2/2 | I29: 41 | J29: นักเรียนใหม่
B30: 29 | C30: 3280 | D30: G-685700-002391 | E30: ด.ช. | F30: ย่าโบซือ | G30: ลาหู่นะ | H30: อ.2/1 | I30: 5 | J30: นักเรียนใหม่
B31: 30 | C31: 3281 | D31: 0-5715-00022-65-4 | E31: ด.ช. | F31: รวมพล | G31: ลาหู่นะ | H31: อ.2/2 | I31: 57 | J31: นักเรียนใหม่
B32: 31 | C32: 3282 | D32: 1-5788-00139-64-1 | E32: ด.ช. | F32: วชิรพงศ์ | G32: แซ่หอ | H32: อ.2/1 | I32: 19 | J32: นักเรียนใหม่
B33: 32 | C33: 3283 | D33: 1-5715-00156-25-0 | E33: ด.ช. | F33: วรินทร | G33: ศิรันดร์กุล | H33: อ.2/1 | I33: 20 | J33: นักเรียนใหม่
B34: 33 | C34: 3284 | D34: 7-5715-00122-93-1 | E34: ด.ช. | F34: สุรชัย | G34: ลาหู่ยี | H34: อ.2/2 | I34: 38 | J34: นักเรียนใหม่
B35: 34 | C35: 3285 | D35: 7-5715-00123-06-7 | E35: ด.ช. | F35: เอกพล | G35: ลาหู่นะ | H35: อ.2/2 | I35: 58 | J35: นักเรียนใหม่
B36: 35 | C36: 3286 | D36: 1-5715-00154-66-4 | E36: ด.ญ. | F36: กัญญา | G36: แซ่เหาะ | H36: อ.2/1 | I36: 11 | J36: นักเรียนใหม่
B37: 36 | C37: 3287 | D37: 1-5799-02080-61-1 | E37: ด.ญ. | F37: กัญญารัตน์ | G37: แซ่จัง | H37: อ.2/1 | I37: 28 | J37: นักเรียนใหม่
B38: 37 | C38: 3288 | D38: 1-5715-00154-85-1 | E38: ด.ญ. | F38: กัญญาวีร์ | G38: แซ่ยี่ | H38: อ.2/1 | I38: 29 | J38: นักเรียนใหม่
B39: 38 | C39: 3289 | D39: 1-5715-00153-82-0 | E39: ด.ญ. | F39: กุลธิดา | G39: แซ่ล้อ | H39: อ.2/2 | I39: 44 | J39: นักเรียนใหม่
B40: 39 | C40: 3290 | D40: G-685700-002421 | E40: ด.ญ. | F40: ขิหมี่ละ | G40: พายอกู่ | H40: อ.2/1 | I40: 31 | J40: นักเรียนใหม่
...

Sheet ย้ายออก
B1: ย้ายออก
B2: 2696 | C2: 1579901641041 | D2: เด็กชาย | E2: บุญยภู | F2: แซ่กุง | G2: รร.ทางจ.เชียงใหม่
B3: 2888 | C3: 1579901629750 | D3: เด็กหญิง | E3: โชติมณี | F3: เกียรติไกรศร | G3: รร.อบจ.เชียงราย
B4: 2620 | C4: 1571500115502 | D4: เด็กชาย | E4: วงศธร | F4: แซ่ลี้ | G4: ไม่มาเรียน
B5: 2624 | C5: 1571500118099 | D5: เด็กชาย | E5: สุรชัย | F5: อายี่ | G5: ออก
B6: 2630 | C6: 1100401604702 | D6: เด็กหญิง | E6: กมลวรรณ | F6: คะเรรัมย์ | G6: ไม่มาเรียน
B7: 2652 | C7: 571500038011 | D7: เด็กหญิง | E7: มนัสพร | F7: ลาหู่นะ | G7: ออก
B8: 2657 | C8: 1571500119001 | D8: เด็กหญิง | E8: รุ่งนภา | F8: แซ่เจียว | G8: ออก
B9: 2532 | C9: G635700044956 | D9: เด็กชาย | E9: อุดร | F9: วิวาระ ออก | G9: ม.2/1
B10: 2552 | C10: G635700044913 | D10: เด็กหญิง | E10: มีมี่ | F10: ลาหู่นะ | G10: ม.2/1
B11: 2666 | C11: 1571500110306 | D11: เด็กชาย | E11: สุภัค | F11: บอแซะ | G11: ม.2/2
B12: 2500 | C12: 1571500113836 | D12: เด็กชาย | E12: ชาติชัย | F12: แหล่งี | G12: ม.2/1
B13: 2764 | C13: 571500037643 | D13: เด็กชาย | E13: จะทิศ | F13: ลาหู่นะ | G13: ป.6 | H13: ไม่มาเรียน
B14: 2951 | C14: 1104301363294 | D14: เด็กชาย | E14: สิทธิโชค | F14: ตามิ | G14: ม.2/2 | H14: กทม.
B15: 2883 | C15: 1571500135236 | D15: เด็กหญิง | E15: สุธิดา | F15: อายี่ | G15: ป.5/2 ย้ายออก รร.ห้วยผึ้ง 12-05-59
B16: 2913 | C16: 579900032514 | D16: เด็กชาย | E16: ราชินทร์ | F16: เฌอหมื่อ | G16: ป.4/2
B17: 3162 | C17: 1579902007493 | D17: เด็กหญิง | E17: วรรณวริน | F17: ศรีอริยทรัพย์ | G17: ป.1/3 EP อบจ.
B18: 3160 | C18: 571500006241 | D18: เด็กหญิง | E18: สโรชา | F18: เชอหมือ | G18: 11 | H18: ไป แม่หม้อ | L18: ไม่มา
B19: 2735 | C19: 1579901605974 | D19: เด็กหญิง | E19: มนรดา | F19: ลาชี
B20: 2705 | C20: 1571500125613 | D20: เด็กชาย | E20: วงศกร | F20: แซ่ลี้
B21: 3022 | C21: 1579901600948 | D21: เด็กชาย | E21: พีระ | F21: แซ่สี่
B22: 2950 | C22: 1104301490261 | D22: เด็กชาย | E22: สิทธิชัย | F22: ตามิ
B23: 2709 | C23: 1571500125788 | D23: เด็กชาย | E23: ศรัณย์พัชร์ | F23: ซูข่า
B24: 2728 | C24: 571500031351 | D24: เด็กหญิง | E24: นาซือคา | F24: ลาหู่นะ
B25: 2693 | C25: 1909803868861 | D25: เด็กชาย | E25: นธนัย | F25: แซ่สู่ง
B26: 2705 | C26: 1571500125613 | D26: เด็กชาย | E26: วงศกร | F26: แซ่ลี้
B27: 2735 | C27: 1579901605974 | D27: เด็กหญิง | E27: มนรดา | F27: ลาชี
B28: 3235 | C28: G675700002277 | D28: เด็กหญิง | E28: นิด | F28: พรมมา

Sheet xxจัดห้อง
A1: ที่ | B1: เลข นร. | C1: เลขประจำตัวประชาชน | D1: ชื่อ1 | E1: ชื่อ2 | F1: ชื่อ3 | G1: ชื่อ4
A2: 29 | B2: 2518 | C2: 1571500114140 | D2: เด็กหญิง | E2: กานต์ธิดา | F2: ปิยะ | G2: ม.2/2
A3: 1 | B3: 2757 | C3: 959800000021 | D3: เด็กชาย | E3: โกวิท | F3: แซ่เจิ้ง | G3: ม.2/1
A4: 19 | B4: 2534 | C4: 571500032005 | D4: เด็กชาย | E4: จะลอ | F4: ลาหู่นะ | G4: ม.2/2
A5: 20 | B5: 2537 | C5: 571500032084 | D5: เด็กชาย | E5: จะสือ | F5: ลาหู่นะ | G5: ม.2/2
A6: 21 | B6: 2513 | C6: 57991044157 | D6: เด็กชาย | E6: จาตุรงค์ | F6: นายคำ | G6: ม.2/2
A7: 2 | B7: 2508 | C7: 7571500115714 | D7: เด็กชาย | E7: ชวิน | F7: ซางสู้ | G7: ม.2/1
A8: 22 | B8: 2507 | C8: 7571500116265 | D8: เด็กชาย | E8: ชานน | F8: คำแดง | G8: ม.2/2
A9: 30 | B9: 2527 | C9: 1571500114298 | D9: เด็กหญิง | E9: ฐิติกา | F9: คาล่า | G9: ม.2/2
A10: 10 | B10: 2816 | C10: 571500038178 | D10: เด็กหญิง | E10: ดวงจิต | F10: คาล่า | G10: ม.2/1
A11: 31 | B11: 2516 | C11: 1571500114433 | D11: เด็กหญิง | E11: ดาว | F11: แซ่ซือ | G11: ม.2/2
A12: 11 | B12: 2522 | C12: 1571500117297 | D12: เด็กหญิง | E12: ธัญญาลักษณ์ | F12: แซ่ฝู | G12: ม.2/1
A13: 3 | B13: 2510 | C13: 7571500115986 | D13: เด็กชาย | E13: ธันวา | F13: ลาหู่นะ | G13: ม.2/1
... A15: 32 | B15: 2519 | C15: 1571500116797 | D15: เด็กหญิง | E15: นรีกานต์ | F15: จะทะ | G15: ม.2/2
A16: 33 | B16: 2560 | C16: G635700085962 | D16: เด็กหญิง | E16: นาดะ | F16: ลาหู่นะ | G16: ม.2/2
A17: 13 | B17: 2550 | C17: 571500031815 | D17: เด็กหญิง | E17: นาบูตะ | F17: ลาหู่นะ | G17: ม.2/1
A18: 14 | B18: 2555 | C18: G635700085989 | D18: เด็กหญิง | E18: นามี | F18: ลาหู่นะ | G18: ม.2/1
A19: 15 | B19: 2526 | C19: 1571500116002 | D19: เด็กหญิง | E19: บัณฑิตา | F19: ลาหู่นะ | G19: ม.2/1
A20: 4 | B20: 2498 | C20: 1579901487238 | D20: เด็กชาย | E20: บุญคเณศ | F20: แซ่จาง | G20: ม.2/1
A21: 5 | B21: 2664 | C21: 1508600027041 | D21: เด็กชาย | E21: ปฏิฎาน | F21: จะกอ | G21: ม.2/1
A22: 36 | B22: 2536 | C22: 571500031505 | D22: นาย | E22: ปุ๊ขิ | F22: ลาหู่นะ | G22: ม.2/2
A23: 6 | B23: 3171 | C23: 1571500104403 | D23: นาย | E23: พนิต | F23: พรวิวัฒน์สกุล | G23: ม.2/1
A24: 16 | B24: 2556 | C24: 571500031971 | D24: เด็กหญิง | E24: มิข่าละ | F24: ลาหู่นะ | G24: ม.2/1
A25: 23 | B25: 2495 | C25: 1571500115995 | D25: เด็กชาย | E25: เมธาสิทธิ์ | F25: ชาติพงค์สกุล | G25: ม.2/2
A26: 24 | B26: 2512 | C26: 7579900078562 | D26: เด็กชาย | E26: ยอดวันใส | F26: ลายใส | G26: ม.2/2
A27: 25 | B27: 2617 | C27: 571500031521 | D27: เด็กชาย | E27: ยะโอ๋ | F27: ลาหู่นะ | G27: ม.2/2
A28: 7 | B28: 2430 | C28: G635700045138 | D28: เด็กชาย | E28: โยฮา | F28: ลาหู่นะ | G28: ม.2/1
A29: 17 | B29: 2523 | C29: 1571500116835 | D29: เด็กหญิง | E29: รุ่งไพลิน | F29: ลาหู่นะ | G29: ม.2/1
A30: 34 | B30: 2517 | C30: 1571500116096 | D30: เด็กหญิง | E30: วิสา | F30: แสงลี | G30: ม.2/2
A31: 9 | B31: 2505 | C31: 1579901471731 | D31: เด็กชาย | E31: ศุภชัย | F31: ลิจา | G31: ม.2/1
A32: 35 | B32: 2531 | C32: 7571500116061 | D32: เด็กหญิง | E32: ศุภลักษณ์ | F32: ลาหู่นะ | G32: ม.2/2
A33: 26 | B33: 2514 | C33: 7571500116184 | D33: เด็กชาย | E33: สมภพ | F33: ลิจาง | G33: ม.2/2
A34: 27 | B34: 2496 | C34: 1579901446353 | D34: เด็กชาย | E34: สิทธินนท์ | F34: แซ่ลี | G34: ม.2/2
A35: 38 | B35: 2666 | C35: 1571500110306 | D35: เด็กชาย | E35: สุภัค | F35: บอแซะ | G35: ม.2/1
A36: 28 | B36: 2506 | C36: 1571500116142 | D36: เด็กชาย | E36: สุรชัย | F36: แซ่ทุ่ง | G36: ม.2/2
A37: 8 | B37: 2540 | C37: 571500032170 | D37: เด็กชาย | E37: หม้อสิ | F37: ลาหู่นะ | G37: ม.2/1
A38: 18 | B38: 2559 | C38: 571500031718 | D38: เด็กหญิง | E38: อาแป๊ะ | F38: อางี่ | G38: ม.2/1
A39: 37 | B39: 2521 | C39: G665700002153 | D39: เด็กหญิง | E39: อามีแต | F39: ลาหู่นะ | G39: ม.2/2
